{"text": "%(asctime)s - %(name)s - %(levelname)s - %(message)s\n\u001b[33m\u001b[1mTraceback (most recent call last):\u001b[0m\n\n  File \"\u001b[32m/home/alexander/Desktop/projects/hashtagbot/hashtag_bot/\u001b[0m\u001b[32m\u001b[1mengine.py\u001b[0m\", line \u001b[33m10\u001b[0m, in \u001b[35m<module>\u001b[0m\n    \u001b[1mloop\u001b[0m\u001b[35m\u001b[1m.\u001b[0m\u001b[1mrun_until_complete\u001b[0m\u001b[1m(\u001b[0m\n    \u001b[36m│    └ \u001b[0m\u001b[36m\u001b[1m<function BaseEventLoop.run_until_complete at 0x7ffb7d204a40>\u001b[0m\n    \u001b[36m└ \u001b[0m\u001b[36m\u001b[1m<_UnixSelectorEventLoop running=True closed=False debug=False>\u001b[0m\n\n  File \"/usr/lib/python3.11/asyncio/base_events.py\", line 640, in run_until_complete\n    self.run_forever()\n    │    └ <function BaseEventLoop.run_forever at 0x7ffb7d2049a0>\n    └ <_UnixSelectorEventLoop running=True closed=False debug=False>\n  File \"/usr/lib/python3.11/asyncio/base_events.py\", line 607, in run_forever\n    self._run_once()\n    │    └ <function BaseEventLoop._run_once at 0x7ffb7d2067a0>\n    └ <_UnixSelectorEventLoop running=True closed=False debug=False>\n  File \"/usr/lib/python3.11/asyncio/base_events.py\", line 1922, in _run_once\n    handle._run()\n    │      └ <function Handle._run at 0x7ffb7d350e00>\n    └ <Handle <TaskStepMethWrapper object at 0x7ffb7b70db40>()>\n> File \"/usr/lib/python3.11/asyncio/events.py\", line 80, in _run\n    self._context.run(self._callback, *self._args)\n    │    │            │    │           │    └ <member '_args' of 'Handle' objects>\n    │    │            │    │           └ <Handle <TaskStepMethWrapper object at 0x7ffb7b70db40>()>\n    │    │            │    └ <member '_callback' of 'Handle' objects>\n    │    │            └ <Handle <TaskStepMethWrapper object at 0x7ffb7b70db40>()>\n    │    └ <member '_context' of 'Handle' objects>\n    └ <Handle <TaskStepMethWrapper object at 0x7ffb7b70db40>()>\n\n\u001b[31m\u001b[1mTypeError\u001b[0m:\u001b[1m start_message() missing 1 required positional argument: 'message'\u001b[0m\n", "record": {"elapsed": {"repr": "0:00:00.012028", "seconds": 0.012028}, "exception": {"type": "TypeError", "value": "start_message() missing 1 required positional argument: 'message'", "traceback": true}, "extra": {}, "file": {"name": "events.py", "path": "/usr/lib/python3.11/asyncio/events.py"}, "function": "_run", "level": {"icon": "❌", "name": "ERROR", "no": 40}, "line": 80, "message": "An error has been caught in function '_run', process 'MainProcess' (27611), thread 'MainThread' (140718128742464):", "module": "events", "name": "asyncio.events", "process": {"id": 27611, "name": "MainProcess"}, "thread": {"id": 140718128742464, "name": "MainThread"}, "time": {"repr": "2023-12-11 23:23:49.874337+03:00", "timestamp": 1702326229.874337}}}
